<?xml version="1.0" encoding="utf-8"?>
<!-- This URDF was automatically created by SolidWorks to URDF Exporter! Originally created by Stephen Brawner (brawner@gmail.com) 
     Commit Version: 1.6.0-4-g7f85cfe  Build Version: 1.6.7995.38578
     For more information, please see http://wiki.ros.org/sw_urdf_exporter -->
<robot
  name="MuRAL One - URDF">
  <link
    name="base_link">
    <inertial>
      <origin
        xyz="2.9159E-06 -0.12971 0.079581"
        rpy="0 0 0" />
      <mass
        value="4.3008" />
      <inertia
        ixx="0.027865"
        ixy="-6.7888E-08"
        ixz="1.8704E-05"
        iyy="0.0097099"
        iyz="1.4822E-07"
        izz="0.027507" />
    </inertial>
    <visual>
      <origin
        xyz="0 0 0"
        rpy="0 0 0" />
      <geometry>
        <mesh
          filename="package://MuRAL One - URDF/meshes/base_link.STL" />
      </geometry>
      <material
        name="">
        <color
          rgba="0.75294 0.75294 0.75294 1" />
      </material>
    </visual>
    <collision>
      <origin
        xyz="0 0 0"
        rpy="0 0 0" />
      <geometry>
        <mesh
          filename="package://MuRAL One - URDF/meshes/base_link.STL" />
      </geometry>
    </collision>
  </link>
  <link
    name="thruster_1">
    <inertial>
      <origin
        xyz="-1.2203E-07 0.012703 -9.8039E-07"
        rpy="0 0 0" />
      <mass
        value="0.0079001" />
      <inertia
        ixx="2.2531E-06"
        ixy="-1.6611E-11"
        ixz="4.9965E-10"
        iyy="3.2817E-06"
        iyz="1.9692E-11"
        izz="2.2524E-06" />
    </inertial>
    <visual>
      <origin
        xyz="0 0 0"
        rpy="0 0 0" />
      <geometry>
        <mesh
          filename="package://MuRAL One - URDF/meshes/thruster_1.STL" />
      </geometry>
      <material
        name="">
        <color
          rgba="1 1 1 1" />
      </material>
    </visual>
    <collision>
      <origin
        xyz="0 0 0"
        rpy="0 0 0" />
      <geometry>
        <mesh
          filename="package://MuRAL One - URDF/meshes/thruster_1.STL" />
      </geometry>
    </collision>
  </link>
  <joint
    name="thruster_1_joint"
    type="continuous">
    <origin
      xyz="0.10762 -0.43754 0.08"
      rpy="0 0 0" />
    <parent
      link="base_link" />
    <child
      link="thruster_1" />
    <axis
      xyz="0 1 0" />
  </joint>
  <link
    name="thruster_2">
    <inertial>
      <origin
        xyz="-2.5591E-06 0.0127 2.4546E-07"
        rpy="0 0 0" />
      <mass
        value="0.007895" />
      <inertia
        ixx="2.2504E-06"
        ixy="2.5519E-11"
        ixz="4.6166E-10"
        iyy="3.2792E-06"
        iyz="1.4283E-11"
        izz="2.2523E-06" />
    </inertial>
    <visual>
      <origin
        xyz="0 0 0"
        rpy="0 0 0" />
      <geometry>
        <mesh
          filename="package://MuRAL One - URDF/meshes/thruster_2.STL" />
      </geometry>
      <material
        name="">
        <color
          rgba="1 1 1 1" />
      </material>
    </visual>
    <collision>
      <origin
        xyz="0 0 0"
        rpy="0 0 0" />
      <geometry>
        <mesh
          filename="package://MuRAL One - URDF/meshes/thruster_2.STL" />
      </geometry>
    </collision>
  </link>
  <joint
    name="thruster_2_joint"
    type="continuous">
    <origin
      xyz="-0.10762 -0.43754 0.08"
      rpy="0 0 0" />
    <parent
      link="base_link" />
    <child
      link="thruster_2" />
    <axis
      xyz="0 1 0" />
  </joint>
  <link
    name="thruster_3">
    <inertial>
      <origin
        xyz="-2.3777E-07 -1.8734E-06 0.0127"
        rpy="0 0 0" />
      <mass
        value="0.0078947" />
      <inertia
        ixx="2.2521E-06"
        ixy="-2.0276E-10"
        ixz="4.0691E-11"
        iyy="2.2505E-06"
        iyz="4.7326E-11"
        izz="3.2792E-06" />
    </inertial>
    <visual>
      <origin
        xyz="0 0 0"
        rpy="0 0 0" />
      <geometry>
        <mesh
          filename="package://MuRAL One - URDF/meshes/thruster_3.STL" />
      </geometry>
      <material
        name="">
        <color
          rgba="1 1 1 1" />
      </material>
    </visual>
    <collision>
      <origin
        xyz="0 0 0"
        rpy="0 0 0" />
      <geometry>
        <mesh
          filename="package://MuRAL One - URDF/meshes/thruster_3.STL" />
      </geometry>
    </collision>
  </link>
  <joint
    name="thruster_3_joint"
    type="continuous">
    <origin
      xyz="0 -0.069955 0.047731"
      rpy="0 0 0" />
    <parent
      link="base_link" />
    <child
      link="thruster_3" />
    <axis
      xyz="0 0 -1" />
  </joint>
</robot>